<?xml version="1.0"?>
<robot xmlns:xacro="http://www.ros.org/wiki/xacro" name="rover_simple">
    <link name="rover_body_assembly">
        <visual>
            <origin xyz="-0.64942341053275720597 0.144281706240071389 0.41190022174550783296" rpy="1.570796326794896558 -0 -1.570796326794896558" />
            <geometry>
                <mesh filename="package://catbot_sim/meshes/linkage.stl"/>
            </geometry>
            <material name="linkage_material">
                <color rgba="0.61568627450980395466 0.81176470588235294379 0.92941176470588238168 1.0"/>
            </material>
        </visual>
        <collision>
            <origin xyz="-0.64942341053275720597 0.144281706240071389 0.41190022174550783296" rpy="1.570796326794896558 -0 -1.570796326794896558" />
            <geometry>
                <mesh filename="package://catbot_sim/meshes/linkage.stl"/>
            </geometry>
        </collision>
        <visual>
            <origin xyz="-0.38297721053275718406 0.144281706240071389 0.41190022174550811052" rpy="1.570796326794896558 -2.4651903288157029456e-32 1.570796326794896558" />
            <geometry>
                <mesh filename="package://catbot_sim/meshes/linkage.stl"/>
            </geometry>
            <material name="linkage_material">
                <color rgba="0.61568627450980395466 0.81176470588235294379 0.92941176470588238168 1.0"/>
            </material>
        </visual>
        <collision>
            <origin xyz="-0.38297721053275718406 0.144281706240071389 0.41190022174550811052" rpy="1.570796326794896558 -2.4651903288157029456e-32 1.570796326794896558" />
            <geometry>
                <mesh filename="package://catbot_sim/meshes/linkage.stl"/>
            </geometry>
        </collision>
        <visual>
            <origin xyz="-0.7158696105327573278 0.144281706240071389 0.41190022174550822154" rpy="1.570796326794896558 1.5959455978986810158e-16 -1.570796326794896558" />
            <geometry>
                <mesh filename="package://catbot_sim/meshes/linkage.stl"/>
            </geometry>
            <material name="linkage_material">
                <color rgba="0.61568627450980395466 0.81176470588235294379 0.92941176470588238168 1.0"/>
            </material>
        </visual>
        <collision>
            <origin xyz="-0.7158696105327573278 0.144281706240071389 0.41190022174550822154" rpy="1.570796326794896558 1.5959455978986810158e-16 -1.570796326794896558" />
            <geometry>
                <mesh filename="package://catbot_sim/meshes/linkage.stl"/>
            </geometry>
        </collision>
        <visual>
            <origin xyz="-0.44942341053275719487 0.144281706240071389 0.41190022174550833256" rpy="1.570796326794896558 -0 1.570796326794896558" />
            <geometry>
                <mesh filename="package://catbot_sim/meshes/linkage.stl"/>
            </geometry>
            <material name="linkage_material">
                <color rgba="0.61568627450980395466 0.81176470588235294379 0.92941176470588238168 1.0"/>
            </material>
        </visual>
        <collision>
            <origin xyz="-0.44942341053275719487 0.144281706240071389 0.41190022174550833256" rpy="1.570796326794896558 -0 1.570796326794896558" />
            <geometry>
                <mesh filename="package://catbot_sim/meshes/linkage.stl"/>
            </geometry>
        </collision>
        <visual>
            <origin xyz="-0.71967961053275719685 0.144281706240071389 0.38696120174550852067" rpy="-0 1.570796326794896558 0" />
            <geometry>
                <mesh filename="package://catbot_sim/meshes/tube.stl"/>
            </geometry>
            <material name="tube_material">
                <color rgba="0.61568627450980395466 0.81176470588235294379 0.92941176470588238168 1.0"/>
            </material>
        </visual>
        <collision>
            <origin xyz="-0.71967961053275719685 0.144281706240071389 0.38696120174550852067" rpy="-0 1.570796326794896558 0" />
            <geometry>
                <mesh filename="package://catbot_sim/meshes/tube.stl"/>
            </geometry>
        </collision>
        <visual>
            <origin xyz="-0.64942341053275720597 -0.065718293759928603226 0.36696120174550855841" rpy="0 -0 0" />
            <geometry>
                <mesh filename="package://catbot_sim/meshes/mainbody.stl"/>
            </geometry>
            <material name="mainbody_material">
                <color rgba="0.61568627450980395466 0.81176470588235294379 0.92941176470588238168 1.0"/>
            </material>
        </visual>
        <collision>
            <origin xyz="-0.64942341053275720597 -0.065718293759928603226 0.36696120174550855841" rpy="0 -0 0" />
            <geometry>
                <mesh filename="package://catbot_sim/meshes/mainbody.stl"/>
            </geometry>
        </collision>
        <inertial>
            <origin xyz="-0.54942341053275722818 0.144281706240071389 0.4240216261077682236" rpy="0 0 0"/>
            <mass value="12.987520001248249457" />
            <inertia ixx="0.21307688536116081712" ixy="-0.00028627745487755802125" ixz="8.5904631591918689485e-18" iyy="0.070805268852694142057" iyz="9.2157184661267876891e-19" izz="0.24529275418898338623" />
        </inertial>
    </link>

    <link name="wheel">
        <visual>
            <origin xyz="0 0 -0.062636400000000036492" rpy="5.8968838415254254708e-77 1.0452720974532386461e-61 2.1423350999071499545e-92" />
            <geometry>
                <mesh filename="package://catbot_sim/meshes/wheel.stl"/>
            </geometry>
            <material name="wheel_material">
                <color rgba="0.61568627450980395466 0.81176470588235294379 0.92941176470588238168 1.0"/>
            </material>
        </visual>
        <collision>
            <origin xyz="0 0 -0.062636400000000036492" rpy="5.8968838415254254708e-77 1.0452720974532386461e-61 2.1423350999071499545e-92" />
            <geometry>
                <mesh filename="package://catbot_sim/meshes/wheel.stl"/>
            </geometry>
        </collision>
        <inertial>
            <origin xyz="-1.5968674542254814519e-18 4.8785457664791327956e-18 -0.031318200000000025185" rpy="0 0 0"/>
            <mass value="1.5079973495144693985" />
            <inertia ixx="0.0028625555945515400794" ixy="6.132552727359467429e-95" ixz="8.1822482799892540537e-64" iyy="0.0028625555945515400794" iyz="1.6880157830979184975e-79" izz="0.0047390521795063313484" />
        </inertial>
    </link>

    <joint name="BackLeft" type="revolute">
        <origin xyz="-0.65323341053275707502 -0.073119749964921099128 0.27801223064467728285" rpy="3.141592653589793116 -1.570796326794896558 0" />
        <parent link="rover_body_assembly" />
        <child link="wheel" />
        <axis xyz="0 0 1"/>
        <limit effort="1" velocity="20" />
        <joint_properties friction="0.0"/>
    </joint>

    <link name="wheel_2">
        <visual>
            <origin xyz="0 0 0" rpy="3.141592653589793116 -0 0" />
            <geometry>
                <mesh filename="package://catbot_sim/meshes/wheel.stl"/>
            </geometry>
            <material name="wheel_material">
                <color rgba="0.61568627450980395466 0.81176470588235294379 0.92941176470588238168 1.0"/>
            </material>
        </visual>
        <collision>
            <origin xyz="0 0 0" rpy="3.141592653589793116 -0 0" />
            <geometry>
                <mesh filename="package://catbot_sim/meshes/wheel.stl"/>
            </geometry>
        </collision>
        <inertial>
            <origin xyz="-1.5968674542254814519e-18 -4.8785457664791327956e-18 -0.031318200000000011307" rpy="0 0 0"/>
            <mass value="1.5079973495144693985" />
            <inertia ixx="0.0028625555945515400794" ixy="0" ixz="0" iyy="0.0028625555945515400794" iyz="0" izz="0.0047390521795063313484" />
        </inertial>
    </link>

    <joint name="BackRight" type="revolute">
        <origin xyz="-0.38297721053275718406 -0.064212542098923047762 0.27801223064467583956" rpy="-1.3684555315672041708e-48 1.570796326794896336 0" />
        <parent link="rover_body_assembly" />
        <child link="wheel_2" />
        <axis xyz="0 0 1"/>
        <limit effort="1" velocity="20" />
        <joint_properties friction="0.0"/>
    </joint>

    <link name="wheel_3">
        <visual>
            <origin xyz="0 0 0" rpy="3.141592653589793116 -1.0452720974532386461e-61 2.1423350999071499545e-92" />
            <geometry>
                <mesh filename="package://catbot_sim/meshes/wheel.stl"/>
            </geometry>
            <material name="wheel_material">
                <color rgba="0.61568627450980395466 0.81176470588235294379 0.92941176470588238168 1.0"/>
            </material>
        </visual>
        <collision>
            <origin xyz="0 0 0" rpy="3.141592653589793116 -1.0452720974532386461e-61 2.1423350999071499545e-92" />
            <geometry>
                <mesh filename="package://catbot_sim/meshes/wheel.stl"/>
            </geometry>
        </collision>
        <inertial>
            <origin xyz="-1.5968674542254814519e-18 -4.8785457664791327956e-18 -0.031318200000000011307" rpy="0 0 0"/>
            <mass value="1.5079973495144693985" />
            <inertia ixx="0.0028625555945515400794" ixy="6.132552727359467429e-95" ixz="-8.1822482799892540537e-64" iyy="0.0028625555945515400794" iyz="-1.6880157830979184975e-79" izz="0.0047390521795063313484" />
        </inertial>
    </link>

    <joint name="FrontLeft" type="revolute">
        <origin xyz="-0.65323341053275718604 0.35277595457906341103 0.27801223064467711632" rpy="1.2325951644078922528e-32 1.570796326794896558 0" />
        <parent link="rover_body_assembly" />
        <child link="wheel_3" />
        <axis xyz="0 0 1"/>
        <limit effort="1" velocity="20" />
        <joint_properties friction="0.0"/>
    </joint>

    <link name="wheel_4">
        <visual>
            <origin xyz="5.5511151231257827021e-17 0 0" rpy="3.141592653589793116 -0 -1.0783263737957629045e-18" />
            <geometry>
                <mesh filename="package://catbot_sim/meshes/wheel.stl"/>
            </geometry>
            <material name="wheel_material">
                <color rgba="0.61568627450980395466 0.81176470588235294379 0.92941176470588238168 1.0"/>
            </material>
        </visual>
        <collision>
            <origin xyz="5.5511151231257827021e-17 0 0" rpy="3.141592653589793116 -0 -1.0783263737957629045e-18" />
            <geometry>
                <mesh filename="package://catbot_sim/meshes/wheel.stl"/>
            </geometry>
        </collision>
        <inertial>
            <origin xyz="5.3914283777032336903e-17 -4.8785457664791327956e-18 -0.031318200000000011307" rpy="0 0 0"/>
            <mass value="1.5079973495144693985" />
            <inertia ixx="0.0028625555945515400794" ixy="-4.4719955787539720653e-20" ixz="0" iyy="0.002862555594551539212" iyz="0" izz="0.0047390521795063313484" />
        </inertial>
    </link>

    <joint name="FrontRight" type="revolute">
        <origin xyz="-0.44561341053275727031 0.36168316244506859558 0.27801223064467472934" rpy="1.570796326794896558 1.5215726907018620739 -1.570796326794896558" />
        <parent link="rover_body_assembly" />
        <child link="wheel_4" />
        <axis xyz="0 0 1"/>
        <limit effort="1" velocity="20" />
        <joint_properties friction="0.0"/>
    </joint>

    <gazebo>
        <plugin filename="ign_ros2_control-system" name="ign_ros2_control::IgnitionROS2ControlPlugin">
            <parameters>$(find catbot_sim)/config/diff_drive_controller_velocity.yaml</parameters>
        </plugin>
    </gazebo>
</robot>
